<?xml version="1.0" encoding="utf-8"?>
<robot name="fr5_ag95">
  <link name="base_link">
    <inertial>
      <origin xyz="-0.00031896 -0.00029673 0.042463" rpy="0 0 0" />
      <mass value="1.6185" />
      <inertia ixx="0.0030836" ixy="1.5354E-05" ixz="-1.9315E-05" iyy="0.0030825" iyz="-1.7918E-05" izz="0.0045209" />
    </inertial>
    <visual>
      <origin xyz="0 0 0" rpy="0 0 0" />
      <geometry>
        <mesh filename="package://dcp_description/meshes/robot/fr5/base_link.STL" />
      </geometry>
      <material name="">
        <color rgba="0.89804 0.91765 0.92941 1" />
      </material>
    </visual>
    <collision>
      <origin xyz="0 0 0" rpy="0 0 0" />
      <geometry>
        <mesh filename="package://dcp_description/meshes/robot/fr5/base_link.STL" />
      </geometry>
    </collision>
  </link>
  <joint name="j1" type="revolute">
    <origin xyz="0 0 0" rpy="0 0 0" />
    <parent link="base_link" />
    <child link="shoulder_link" />
    <axis xyz="0 0 1" />
    <limit lower="-3.0543" upper="3.0543" effort="150" velocity="3.15" />
  </joint>
  <link name="shoulder_link">
    <inertial>
      <origin xyz="5.0029E-07 -0.0040922 0.14629" rpy="0 0 0" />
      <mass value="4.3771" />
      <inertia ixx="0.010731" ixy="-8.0587E-09" ixz="-3.6773E-08" iyy="0.010408" iyz="0.00012853" izz="0.0081793" />
    </inertial>
    <visual>
      <origin xyz="0 0 0" rpy="0 0 0" />
      <geometry>
        <mesh filename="package://dcp_description/meshes/robot/fr5/shoulder_link.STL" />
      </geometry>
      <material name="">
        <color rgba="0.89804 0.91765 0.92941 1" />
      </material>
    </visual>
    <collision>
      <origin xyz="0 0 0" rpy="0 0 0" />
      <geometry>
        <mesh filename="package://dcp_description/meshes/robot/fr5/shoulder_link.STL" />
      </geometry>
    </collision>
  </link>
  <joint name="j2" type="revolute">
    <origin xyz="0 0 0.152" rpy="1.5708 0 0" />
    <parent link="shoulder_link" />
    <child link="upperarm_link" />
    <axis xyz="0 0 1" />
    <limit lower="-4.6251" upper="1.4835" effort="150" velocity="3.15" />
  </joint>
  <link name="upperarm_link">
    <inertial>
      <origin xyz="-0.2125 -5.7643E-09 0.1346" rpy="0 0 0" />
      <mass value="14.458" />
      <inertia ixx="0.028392" ixy="-1.337E-07" ixz="-3.9895E-09" iyy="0.4559" iyz="4.214E-08" izz="0.44974" />
    </inertial>
    <visual>
      <origin xyz="0 0 0" rpy="0 0 0" />
      <geometry>
        <mesh filename="package://dcp_description/meshes/robot/fr5/upperarm_link.STL" />
      </geometry>
      <material name="">
        <color rgba="0.89804 0.91765 0.92941 1" />
      </material>
    </visual>
    <collision>
      <origin xyz="0 0 0" rpy="0 0 0" />
      <geometry>
        <mesh filename="package://dcp_description/meshes/robot/fr5/upperarm_link.STL" />
      </geometry>
    </collision>
  </link>
  <joint name="j3" type="revolute">
    <origin xyz="-0.425 0 0" rpy="0 0 0" />
    <parent link="upperarm_link" />
    <child link="forearm_link" />
    <axis xyz="0 0 1" />
    <limit lower="-2.8274" upper="2.8274" effort="150" velocity="3.15" />
  </joint>
  <link name="forearm_link">
    <inertial>
      <origin xyz="-0.18793 -8.4503E-07 0.0066357" rpy="0 0 0" />
      <mass value="7.6737" />
      <inertia ixx="0.0085096" ixy="2.1613E-06" ixz="-0.0068678" iyy="0.16971" iyz="3.7086E-08" izz="0.16854" />
    </inertial>
    <visual>
      <origin xyz="0 0 0" rpy="0 0 0" />
      <geometry>
        <mesh filename="package://dcp_description/meshes/robot/fr5/forearm_link.STL" />
      </geometry>
      <material name="">
        <color rgba="0.89804 0.91765 0.92941 1" />
      </material>
    </visual>
    <collision>
      <origin xyz="0 0 0" rpy="0 0 0" />
      <geometry>
        <mesh filename="package://dcp_description/meshes/robot/fr5/forearm_link.STL" />
      </geometry>
    </collision>
  </link>
  <joint name="j4" type="revolute">
    <origin xyz="-0.39501 0 0" rpy="0 0 0" />
    <parent  link="forearm_link" />
    <child link="wrist1_link" />
    <axis xyz="0 0 1" />
    <limit lower="-4.6251" upper="1.4835" effort="28" velocity="3.2" />
  </joint>
  <link name="wrist1_link">
    <inertial>
      <origin xyz="4.98E-07 -0.003754 0.097155" rpy="0 0 0" />
      <mass value="1.6266" />
      <inertia ixx="0.00216" ixy="4.888E-09" ixz="3.1528E-08" iyy="0.0015455" iyz="3.7678E-05" izz="0.0019902" />
    </inertial>
    <visual>
      <origin xyz="0 0 0" rpy="0 0 0" />
      <geometry>
        <mesh filename="package://dcp_description/meshes/robot/fr5/wrist1_link.STL" />
      </geometry>
      <material name="">
        <color rgba="0.89804 0.91765 0.92941 1" />
      </material>
    </visual>
    <collision>
      <origin xyz="0 0 0" rpy="0 0 0" />
      <geometry>
        <mesh filename="package://dcp_description/meshes/robot/fr5/wrist1_link.STL" />
      </geometry>
    </collision>
  </link>
  <joint name="j5" type="revolute">
    <origin xyz="0 0 0.1021" rpy="1.5708 0 0" />
    <parent link="wrist1_link" />
    <child link="wrist2_link" />
    <axis xyz="0 0 1" />
    <limit lower="-3.0543" upper="3.0543" effort="28" velocity="3.2" />
  </joint>
  <link
    name="wrist2_link">
    <inertial>
      <origin xyz="-4.5588E-07 0.0038617 0.098257" rpy="0 0 0" />
      <mass value="1.5812" />
      <inertia ixx="0.0020612" ixy="8.7064E-09" ixz="-3.4742E-08" iyy="0.0014477" iyz="-2.8534E-05" izz="0.0019573" />
    </inertial>
    <visual>
      <origin xyz="0 0 0" rpy="0 0 0" />
      <geometry>
        <mesh filename="package://dcp_description/meshes/robot/fr5/wrist2_link.STL" />
      </geometry>
      <material name="">
        <color rgba="0.89804 0.91765 0.92941 1" />
      </material>
    </visual>
    <collision>
      <origins xyz="0 0 0" rpy="0 0 0" />
      <geometry>
        <mesh filename="package://dcp_description/meshes/robot/fr5/wrist2_link.STL" />
      </geometry>
    </collision>
  </link>
  <joint name="j6" type="revolute">
    <origin xyz="0 0 0.102" rpy="-1.5708 0 0" />
    <parent link="wrist2_link" />
    <child link="wrist3_link" />
    <axis xyz="0 0 1" />
    <limit lower="-3.0543" upper="3.0543" effort="28" velocity="3.2" />
  </joint>
  <link name="wrist3_link">
    <inertial>
      <origin xyz="7.7496E-05 1.7751E-05 0.076122" rpy="0 0 0" />
      <mass value="0.52542" />
      <inertia ixx="0.00027721" ixy="-1.8677E-09" ixz="-1.188E-07" iyy="0.00027839" iyz="2.2607E-07" izz="0.00041605" />
    </inertial>
    <visual>
      <origin xyz="0 0 0" rpy="0 0 0" />
      <geometry>
        <mesh filename="package://dcp_description/meshes/robot/fr5/wrist3_link.STL" />
      </geometry>
      <material name="">
        <color rgba="0.89804 0.91765 0.92941 1" />
      </material>
    </visual>
    <collision>
      <origin xyz="0 0 0" rpy="0 0 0" />
      <geometry>
        <mesh filename="package://dcp_description/meshes/robot/fr5/wrist3_link.STL" />
      </geometry>
    </collision>
  </link>
  <joint name="wrist3-flange" type="fixed">
    <parent link="wrist3_link"/>
    <child link="flange"/>
    <origin rpy="0 -1.5707963267948966 -1.5707963267948966" xyz="0 0 0.1"/>
  </joint>
  <link name="flange"/>
  <joint name="flange-tool0" type="fixed">
    <origin rpy="1.5707963267948966 0 1.5707963267948966" xyz="0 0 0"/>
    <parent link="flange"/>
    <child link="tool0"/>
  </joint>
  <link name="tool0"/>

  <!-- Gripper -->
  <link name="robotiq_85_base_link">
    <visual>
      <geometry>
        <mesh filename="package://dcp_description/meshes/gripper/2f_85/visual/robotiq_base.dae"/>
      </geometry>
    </visual>
    <collision>
      <geometry>
        <mesh filename="package://dcp_description/meshes/gripper/2f_85/collision/robotiq_base.stl"/>
      </geometry>
    </collision>
    <inertial>
      <origin rpy="0 0 0" xyz="0.0 2.274e-05 0.03232288"/>
      <mass value="6.6320197e-01"/>
      <inertia ixx="5.1617816e-04" ixy="2.936e-8" ixz="0.0" iyy="5.8802208e-04" iyz="-3.2296e-7" izz="3.9462776e-04"/>
    </inertial>
  </link>
  <link name="robotiq_85_left_knuckle_link">
    <visual>
      <geometry>
        <mesh filename="package://dcp_description/meshes/gripper/2f_85/visual/left_knuckle.dae"/>
      </geometry>
    </visual>
    <collision>
      <geometry>
        <mesh filename="package://dcp_description/meshes/gripper/2f_85/collision/left_knuckle.stl"/>
      </geometry>
    </collision>
    <inertial>
      <origin rpy="0 0 0" xyz="0.01213197 0.0002 -0.00058647"/>
      <mass value="1.384773208e-02"/>
      <inertia ixx="3.5232e-7" ixy="0.0" ixz="1.1744e-7" iyy="2.31944e-6" iyz="0" izz="2.23136e-6"/>
    </inertial>
  </link>
  <link name="robotiq_85_right_knuckle_link">
    <visual>
      <geometry>
        <mesh filename="package://dcp_description/meshes/gripper/2f_85/visual/right_knuckle.dae"/>
      </geometry>
    </visual>
    <collision>
      <geometry>
        <mesh filename="package://dcp_description/meshes/gripper/2f_85/collision/right_knuckle.stl"/>
      </geometry>
    </collision>
    <inertial>
      <origin rpy="0 0 0" xyz="-0.01213197 0.0002 -0.00058647"/>
      <mass value="1.384773208e-02"/>
      <inertia ixx="3.5232e-7" ixy="0.0" ixz="-1.1744e-7" iyy="2.31944e-6" iyz="0.0" izz="2.23136e-6"/>
    </inertial>
  </link>
  <link name="robotiq_85_left_finger_link">
    <visual>
      <geometry>
        <mesh filename="package://dcp_description/meshes/gripper/2f_85/visual/left_finger.dae"/>
      </geometry>
    </visual>
    <collision>
      <geometry>
        <mesh filename="package://dcp_description/meshes/gripper/2f_85/collision/left_finger.stl"/>
      </geometry>
    </collision>
    <inertial>
      <origin rpy="0 0 0" xyz="0.00346899 -0.00079447 0.01867121"/>
      <mass value="4.260376752e-02"/>
      <inertia ixx="1.385792000000000e-05" ixy="0.0" ixz="-2.17264e-06" iyy="1.183208e-05" iyz="0.0" izz="5.19672e-06"/>
    </inertial>
  </link>
  <link name="robotiq_85_right_finger_link">
    <visual>
      <geometry>
        <mesh filename="package://dcp_description/meshes/gripper/2f_85/visual/right_finger.dae"/>
      </geometry>
    </visual>
    <collision>
      <geometry>
        <mesh filename="package://dcp_description/meshes/gripper/2f_85/collision/right_finger.stl"/>
      </geometry>
    </collision>
    <inertial>
      <origin rpy="0 0 0" xyz="-0.00346899 -5.53e-06 0.01867121"/>
      <mass value="4.260376752000000e-02"/>
      <inertia ixx="1.385792e-05" ixy="0.0" ixz="2.17264e-06" iyy="1.183208e-05" iyz="0.0" izz="5.19672e-06"/>
    </inertial>
  </link>
  <link name="robotiq_85_left_inner_knuckle_link">
    <visual>
      <geometry>
        <mesh filename="package://dcp_description/meshes/gripper/2f_85/visual/left_inner_knuckle.dae"/>
      </geometry>
    </visual>
    <collision>
      <geometry>
        <mesh filename="package://dcp_description/meshes/gripper/2f_85/collision/left_inner_knuckle.stl"/>
      </geometry>
    </collision>
    <inertial>
      <origin rpy="0 0 0" xyz="0.01897699 0.00015001 0.02247101"/>
      <mass value="2.969376448e-02"/>
      <inertia ixx="9.57136e-06" ixy="0.0" ixz="-3.93424e-06" iyy="8.69056e-06" iyz="0.0" izz="8.19144e-06"/>
    </inertial>
  </link>
  <link name="robotiq_85_right_inner_knuckle_link">
    <visual>
      <geometry>
        <mesh filename="package://dcp_description/meshes/gripper/2f_85/visual/right_inner_knuckle.dae"/>
      </geometry>
    </visual>
    <collision>
      <geometry>
        <mesh filename="package://dcp_description/meshes/gripper/2f_85/collision/right_inner_knuckle.stl"/>
      </geometry>
    </collision>
    <inertial>
      <origin rpy="0 0 0" xyz="-0.01926824 5.001e-05 0.02222178"/>
      <mass value="2.969376448e-02"/>
      <inertia ixx="9.42456e-06" ixy="0.0" ixz="3.9636e-06" iyy="8.69056e-06" iyz="0.0" izz="8.33824e-06"/>
    </inertial>
  </link>
  <link name="robotiq_85_left_finger_tip_link">
    <visual>
      <geometry>
        <mesh filename="package://dcp_description/meshes/gripper/2f_85/visual/left_finger_tip.dae"/>
      </geometry>
    </visual>
    <collision>
      <geometry>
        <mesh filename="package://dcp_description/meshes/gripper/2f_85/collision/left_finger_tip.stl"/>
      </geometry>
      <surface>
        <friction>
          <ode>
            <mu1>100000.0</mu1>
            <mu2>100000.0</mu2>
          </ode>
        </friction>
        <contact>
          <ode>
            <kp>1e+5</kp>
            <kd>1</kd>
            <soft_cfm>0</soft_cfm>
            <soft_erp>0.2</soft_erp>
            <minDepth>0.002</minDepth>
            <maxVel>0</maxVel>
          </ode>
        </contact>
      </surface>
    </collision>
    <inertial>
      <origin rpy="0 0 0" xyz="-0.01456706 -0.0008 0.01649701"/>
      <mass value="4.268588744e-02"/>
      <inertia ixx="1.048152e-05" ixy="0.0" ixz="3.5232e-6" iyy="1.197888e-05" iyz="0.0" izz="4.22784e-06"/>
    </inertial>
  </link>
  <link name="robotiq_85_right_finger_tip_link">
    <visual>
      <geometry>
        <mesh filename="package://dcp_description/meshes/gripper/2f_85/visual/right_finger_tip.dae"/>
      </geometry>
    </visual>
    <collision>
      <geometry>
        <mesh filename="package://dcp_description/meshes/gripper/2f_85/collision/right_finger_tip.stl"/>
      </geometry>
      <surface>
        <friction>
          <ode>
            <mu1>100000.0</mu1>
            <mu2>100000.0</mu2>
          </ode>
        </friction>
        <contact>
          <ode>
            <kp>1e+5</kp>
            <kd>1</kd>
            <soft_cfm>0</soft_cfm>
            <soft_erp>0.2</soft_erp>
            <minDepth>0.002</minDepth>
            <maxVel>0</maxVel>
          </ode>
        </contact>
      </surface>
    </collision>
    <inertial>
      <origin rpy="0 0 0" xyz="0.01456706 5e-05 0.01649701"/>
      <mass value="4.268588744e-02"/>
      <inertia ixx="1.048152e-05" ixy="0.0" ixz="-3.5232e-06" iyy="1.197888e-05" iyz="0.0" izz="4.22784e-06"/>
    </inertial>
  </link>
  <joint name="robotiq_85_base_joint" type="fixed">
    <parent link="tool0"/>
    <child link="robotiq_85_base_link"/>
    <origin rpy="0 0 0" xyz="0 0 0"/>
  </joint>
  <joint name="robotiq_85_left_knuckle_joint" type="revolute">
    <parent link="robotiq_85_base_link"/>
    <child link="robotiq_85_left_knuckle_link"/>
    <axis xyz="0 -1 0"/>
    <origin rpy="0 0 0" xyz="0.03060114 0.0 0.05490452"/>
    <limit effort="50" lower="0.0" upper="0.8" velocity="0.5"/>
  </joint>
  <joint name="robotiq_85_right_knuckle_joint" type="revolute">
    <parent link="robotiq_85_base_link"/>
    <child link="robotiq_85_right_knuckle_link"/>
    <axis xyz="0 -1 0"/>
    <origin rpy="0 0 0" xyz="-0.03060114 0.0 0.05490452"/>
    <limit effort="50" lower="-0.8" upper="0.0" velocity="0.5"/>
    <mimic joint="robotiq_85_left_knuckle_joint" multiplier="-1"/>
  </joint>
  <joint name="robotiq_85_left_finger_joint" type="fixed">
    <parent link="robotiq_85_left_knuckle_link"/>
    <child link="robotiq_85_left_finger_link"/>
    <origin rpy="0 0 0" xyz="0.03152616 0.0 -0.00376347"/>
  </joint>
  <joint name="robotiq_85_right_finger_joint" type="fixed">
    <parent link="robotiq_85_right_knuckle_link"/>
    <child link="robotiq_85_right_finger_link"/>
    <origin rpy="0 0 0" xyz="-0.03152616 0.0 -0.00376347"/>
  </joint>
  <joint name="robotiq_85_left_inner_knuckle_joint" type="continuous">
    <parent link="robotiq_85_base_link"/>
    <child link="robotiq_85_left_inner_knuckle_link"/>
    <axis xyz="0 -1 0"/>
    <origin rpy="0 0 0" xyz="0.0127 0.0 0.06142"/>
    <limit effort="1000" lower="-0.8757" upper="0.8757" velocity="2.0"/>
    <mimic joint="robotiq_85_left_knuckle_joint"/>
  </joint>
  <joint name="robotiq_85_right_inner_knuckle_joint" type="continuous">
    <parent link="robotiq_85_base_link"/>
    <child link="robotiq_85_right_inner_knuckle_link"/>
    <axis xyz="0 -1 0"/>
    <origin rpy="0 0 0" xyz="-0.0127 0.0 0.06142"/>
    <limit effort="1000" lower="-0.8757" upper="0.8757" velocity="2.0"/>
    <mimic joint="robotiq_85_left_knuckle_joint" multiplier="-1"/>
  </joint>
  <joint name="robotiq_85_left_finger_tip_joint" type="continuous">
    <parent link="robotiq_85_left_finger_link"/>
    <child link="robotiq_85_left_finger_tip_link"/>
    <axis xyz="0 -1 0"/>
    <origin rpy="0 0 0" xyz="0.00563134 0.0 0.04718515"/>
    <limit effort="1000" lower="-0.8757" upper="0.8757" velocity="2.0"/>
    <mimic joint="robotiq_85_left_knuckle_joint" multiplier="-1"/>
  </joint>
  <joint name="robotiq_85_right_finger_tip_joint" type="continuous">
    <parent link="robotiq_85_right_finger_link"/>
    <child link="robotiq_85_right_finger_tip_link"/>
    <axis xyz="0 -1 0"/>
    <origin rpy="0 0 0" xyz="-0.00563134 0.0 0.04718515"/>
    <limit effort="1000" lower="-0.8757" upper="0.8757" velocity="2.0"/>
    <mimic joint="robotiq_85_left_knuckle_joint"/>
  </joint>
  <link name="gripper_frame">
    <inertial>
      <!-- Dummy inertial parameters to avoid link lumping-->
      <mass value="0.01"/>
      <inertia ixx="0.0001" ixy="0.0" ixz="0.0" iyy="0.0001" iyz="0.0" izz="0.0001"/>
      <origin rpy="0 0 0" xyz="0 0 0"/>
    </inertial>
  </link>
  <joint name="gripper_joint" type="fixed">
    <origin rpy="0 0 0" xyz="0 0 0"/>
    <parent link="robotiq_85_base_link"/>
    <child link="gripper_frame"/>
  </joint>

  <link name="grasp_frame">
    <inertial>
      <!-- Dummy inertial parameters to avoid link lumping-->
      <mass value="0.01"/>
      <inertia ixx="0.0001" ixy="0.0" ixz="0.0" iyy="0.0001" iyz="0.0" izz="0.0001"/>
      <origin rpy="0 0 0" xyz="0 0 0"/>
    </inertial>
  </link>
  <joint name="grasp_joint" type="fixed">
    <origin rpy="0 0 0" xyz="0 0 0.15"/>
    <axis xyz="0 0 1"/>
    <parent link="gripper_frame"/>
    <child link="grasp_frame"/>
  </joint>
  
</robot>